Workbook

Sheet README
A1: LIVING IKON BOM TRACKER AND COSTING WORKBOOK, 5 Oct 2026
A2: Same format and rate card as the PLV BOM Costing Workbook v3 (1 Oct 2026).
A4: WHAT THIS IS
B5: ITEMS lists the 36 items of the LEXI, NEW HOI AN and SIENNA catalogues, grouped by collection. Each item already has its own tab (tab name = item code; blue tabs LEXI, green NEW HOI AN, orange SIENNA).
B6: The operator reads the drawing and types component sizes, quantities and bought-in prices. Volume m³, face m², tier (grade A / A-CURVED / B / C / D) and all costs are calculated from the RATES tab. ITEMS shows status and unit cost per item for the quotation.
A8: COLOURS
B9: Blue text / white cell = you type here. Yellow cell = must be filled (item code, hardware unit price). Grey = calculated, do not type. Light blue = cost from the rate card, do not type.
A11: STEPS FOR EACH ITEM
A12: 1 | B12: Open the item tab. Code, name, collection / room, overall size and catalogue link are filled from ITEMS. If one is wrong or empty, correct it on ITEMS (or type over it).
A13: 2 | B13: Paste the DRAWING LINK on ITEMS column I (it shows on the tab). Choose FINISH RECIPE and FLATPACK Y/N. Flatpack: one PACKING row per box (inside size). Assembled: leave the boxes empty.
A14: 3 | B14: SOLID WOOD: one line per component: material, name, L, W, T in mm, qty per ONE item, EXPOSED Y/N, CURVED Y/N. The m³, m², tier and cost appear by themselves.
A15: 4 | B15: PANELS: one line per panel: panel type, L, W, T, qty, exposed faces 0 / 1 / 2. Round, oversize or laminated panel with no size: type the number of sheets in SHEETS (manual).
A16: 5 | B16: HARDWARE & BOUGHT-IN: every purchased part or outside job: description, qty, UOM and UNIT PRICE IDR. This includes drawer runners, hinges, handles, SIENNA metal frames, NEW HOI AN rattan, mirror glass, chair fabric and foam.
B17: The EXAMPLE OV-505 B tab is a filled-in item (a Standard Maldives shelf) showing what a finished tab looks like.
A18: 6 | B18: Look at the CHECK column and "Open input checks" under the summary. All must be OK / 0. Then ITEMS shows the item as "costed".
A19: 7 | B19: New item not in the catalogues: add it on a spare row of ITEMS, then right-click TEMPLATE, Duplicate, rename the copy to the item code and type the code in C1.
A21: LANGKAH SINGKAT (BAHASA INDONESIA)
A22: 1 | B22: Buka tab item (nama tab = kode item). Kode, nama, koleksi / ruangan, ukuran keseluruhan dan link katalog terisi otomatis dari ITEMS. Kalau salah atau kosong, perbaiki di ITEMS.
A23: 2 | B23: Tempel link gambar di ITEMS kolom I. Isi komponen kayu solid (ukuran mm, qty per 1 item, EXPOSED Y/N, CURVED Y/N), panel, lalu hardware / barang beli dengan HARGA SATUAN (IDR).
A24: 3 | B24: Sel abu-abu dan biru muda dihitung sistem, jangan diketik. Kolom CHECK harus OK semua. Tab RATES dan LISTS jangan diubah.
A26: RULES BUILT INTO THE FORMULAS
B27: Tier (solid wood): D = volume under 0.0005 m³ and under 300 mm · C = not exposed · A-CURVED = curved / wide board · B = section up to 40 × 40 mm and up to 1500 mm long, or shorter than 1000 mm · A = 1000 mm and longer. TIER OVERRIDE beats the rule.
B28: Tier rate = (log price + processing) × yield + carpentry labour, per m³ of finished component. Meranti = sawn price × yield + labour. Species OTHER has no rate: price it as a bought-in line.
B29: Panels: pieces per sheet from the 2440 × 1220 sheet with 5 mm kerf; whole sheets charged, unless waste on the last sheet is over 25% (then the fraction + 5% handling).
B30: Finishing: four lines (finishing materials, sanding materials, sanding labour, finishing labour) × exposed m². Exposed m² = one face (L × W × qty) per exposed solid component + exposed panel faces. Recipe NONE (RAW) = no finishing cost.
B31: Packing: carton = box size + 40 mm each way; cost = carton m² × rate + carton m³ × packing labour. Misc 5% on direct cost, overhead % on direct + misc.
A33: STILL OPEN
B34: Materials: the catalogues specify oak, Vic ash, MDF with oak veneer, rattan and metal frames. RATES only has teak, mindi, meranti and plywood with teak / mindi veneer. Decide the build material per collection, or add rates, before the costs are used for a quotation.
B35: Rate card: teak and mindi log prices are implied from the STMV ledger, not nota prices; yields for tiers A, B and D are by judgement; fasteners total, veneer prices and packing labour are estimates. Changing a blue cell on RATES re-costs every item.
B36: Finishing m² counts one face per component. For slatted items this is well below the real painted surface.
B37: The workbook gives factory cost per unit in IDR. Margin, currency and freight for the quotation are not in it.

Sheet ITEMS
A1: LIVING IKON BOM TRACKER: ITEM LIST AND COST ROLL-UP (LEXI, NEW HOI AN, SIENNA catalogues 2026)
A2: One tab per item, tab name = ITEM CODE exactly as in column C. Columns J to T, Y and Z fill by themselves from the item tab. Codes, names and sizes are as printed in the catalogues (L = length or width, W = width or depth). Blue = type or correct here.
A4: NO | B4: COLLECTION | C4: ITEM CODE (= tab name) | D4: ITEM NAME | E4: L mm | F4: W mm | G4: H mm | H4: ORDER QTY | I4: DRAWING LINK | J4: STATUS | K4: TIMBER + FASTENERS | L4: PANELS | M4: FINISHING (4 lines) | N4: HARDWARE & BOUGHT-IN | O4: PACKING | P4: MISC 4% | Q4: DIRECT COST IDR (HPP) | R4: ORDER TOTAL IDR | S4: CARTON m³ / unit | T4: OPEN CHECKS | U4: COSTED BY / NOTE | V4: CATALOGUE LINK | W4: ROOM | X4: CATALOGUE MATERIAL / FINISH | Y4: SOLID WOOD m³ / unit | Z4: FINISHING m² / unit | AA4: PANELS + HARDWARE (status check)
A6: 1 | B6: NEW HOI AN | C6: LV453-B61 | D6: DRESSER 6 DRAWERS | E6: 1500 | F6: 450 | G6: 820 | H6: 1 | I6: LV453 - B61 - DRESSER 6 DRAWERS.pdf | J6: =IF($C6="","",IF(ISERROR(INDIRECT("'"&$C6&"'!C1")),"no tab yet",IF(N(Y6)+N(AA6)=0,"tab empty",IF(N(T6)>0,"check inputs","costed")))) | K6: =IF(OR($J6="",$J6="no tab yet",$J6="tab empty"),"",IFERROR(INDIRECT("'"&$C6&"'!D87")+INDIRECT("'"&$C6&"'!D88"),"")) | L6: =IF(OR($J6="",$J6="no tab yet",$J6="tab empty"),"",IFERROR(INDIRECT("'"&$C6&"'!D89")+0,"")) | M6: =IF(OR($J6="",$J6="no tab yet",$J6="tab empty"),"",IFERROR(SUM(INDIRECT("'"&$C6&"'!D90:D93")),"")) | N6: =IF(OR($J6="",$J6="no tab yet",$J6="tab empty"),"",IFERROR(INDIRECT("'"&$C6&"'!D94")+0,"")) | O6: =IF(OR($J6="",$J6="no tab yet",$J6="tab empty"),"",IFERROR(INDIRECT("'"&$C6&"'!D95")+0,"")) | P6: =IF(OR($J6="",$J6="no tab yet",$J6="tab empty"),"",IFERROR(INDIRECT("'"&$C6&"'!D97"),"")) | Q6: =IF(OR($J6="",$J6="no tab yet",$J6="tab empty"),"",IFERROR(INDIRECT("'"&$C6&"'!D98")+0,"")) | R6: =IF(AND(ISNUMBER(H6),ISNUMBER(Q6)),H6*Q6,"") | S6: =IFERROR(INDIRECT("'"&$C6&"'!D86")+0,"") | T6: =IFERROR(INDIRECT("'"&$C6&"'!D102")+0,"") | Y6: =IFERROR(INDIRECT("'"&$C6&"'!D82")+0,"") | Z6: =IFERROR(INDIRECT("'"&$C6&"'!D84")+0,"") | AA6: =IFERROR(INDIRECT("'"&$C6&"'!D89")+INDIRECT("'"&$C6&"'!D94"),"")
J30: =IF($C30="","",IF(ISERROR(INDIRECT("'"&$C30&"'!C1")),"no tab yet",IF(N(Y30)+N(AA30)=0,"tab empty",IF(N(T30)>0,"check inputs","costed")))) | K30: =IF(OR($J30="",$J30="no tab yet",$J30="tab empty"),"",IFERROR(INDIRECT("'"&$C30&"'!D87")+INDIRECT("'"&$C30&"'!D88"),"")) | L30: =IF(OR($J30="",$J30="no tab yet",$J30="tab empty"),"",IFERROR(INDIRECT("'"&$C30&"'!D89")+0,"")) | M30: =IF(OR($J30="",$J30="no tab yet",$J30="tab empty"),"",IFERROR(SUM(INDIRECT("'"&$C30&"'!D90:D93")),"")) | N30: =IF(OR($J30="",$J30="no tab yet",$J30="tab empty"),"",IFERROR(INDIRECT("'"&$C30&"'!D94")+0,"")) | O30: =IF(OR($J30="",$J30="no tab yet",$J30="tab empty"),"",IFERROR(INDIRECT("'"&$C30&"'!D95")+0,"")) | P30: =IF(OR($J30="",$J30="no tab yet",$J30="tab empty"),"",IFERROR(INDIRECT("'"&$C30&"'!D97"),"")) | Q30: =IF(OR($J30="",$J30="no tab yet",$J30="tab empty"),"",IFERROR(INDIRECT("'"&$C30&"'!D98")+0,"")) | R30: =IF(AND(ISNUMBER(H30),ISNUMBER(Q30)),H30*Q30,"") | S30: =IFERROR(INDIRECT("'"&$C30&"'!D86")+0,"") | T30: =IFERROR(INDIRECT("'"&$C30&"'!D102")+0,"") | Y30: =IFERROR(INDIRECT("'"&$C30&"'!D82")+0,"") | Z30: =IFERROR(INDIRECT("'"&$C30&"'!D84")+0,"") | AA30: =IFERROR(INDIRECT("'"&$C30&"'!D89")+INDIRECT("'"&$C30&"'!D94"),"")
J31: =IF($C31="","",IF(ISERROR(INDIRECT("'"&$C31&"'!C1")),"no tab yet",IF(N(Y31)+N(AA31)=0,"tab empty",IF(N(T31)>0,"check inputs","costed")))) | K31: =IF(OR($J31="",$J31="no tab yet",$J31="tab empty"),"",IFERROR(INDIRECT("'"&$C31&"'!D87")+INDIRECT("'"&$C31&"'!D88"),"")) | L31: =IF(OR($J31="",$J31="no tab yet",$J31="tab empty"),"",IFERROR(INDIRECT("'"&$C31&"'!D89")+0,"")) | M31: =IF(OR($J31="",$J31="no tab yet",$J31="tab empty"),"",IFERROR(SUM(INDIRECT("'"&$C31&"'!D90:D93")),"")) | N31: =IF(OR($J31="",$J31="no tab yet",$J31="tab empty"),"",IFERROR(INDIRECT("'"&$C31&"'!D94")+0,"")) | O31: =IF(OR($J31="",$J31="no tab yet",$J31="tab empty"),"",IFERROR(INDIRECT("'"&$C31&"'!D95")+0,"")) | P31: =IF(OR($J31="",$J31="no tab yet",$J31="tab empty"),"",IFERROR(INDIRECT("'"&$C31&"'!D97"),"")) | Q31: =IF(OR($J31="",$J31="no tab yet",$J31="tab empty"),"",IFERROR(INDIRECT("'"&$C31&"'!D98")+0,"")) | R31: =IF(AND(ISNUMBER(H31),ISNUMBER(Q31)),H31*Q31,"") | S31: =IFERROR(INDIRECT("'"&$C31&"'!D86")+0,"") | T31: =IFERROR(INDIRECT("'"&$C31&"'!D102")+0,"") | Y31: =IFERROR(INDIRECT("'"&$C31&"'!D82")+0,"") | Z31: =IFERROR(INDIRECT("'"&$C31&"'!D84")+0,"") | AA31: =IFERROR(INDIRECT("'"&$C31&"'!D89")+INDIRECT("'"&$C31&"'!D94"),"")
J32: =IF($C32="","",IF(ISERROR(INDIRECT("'"&$C32&"'!C1")),"no tab yet",IF(N(Y32)+N(AA32)=0,"tab empty",IF(N(T32)>0,"check inputs","costed")))) | K32: =IF(OR($J32="",$J32="no tab yet",$J32="tab empty"),"",IFERROR(INDIRECT("'"&$C32&"'!D87")+INDIRECT("'"&$C32&"'!D88"),"")) | L32: =IF(OR($J32="",$J32="no tab yet",$J32="tab empty"),"",IFERROR(INDIRECT("'"&$C32&"'!D89")+0,"")) | M32: =IF(OR($J32="",$J32="no tab yet",$J32="tab empty"),"",IFERROR(SUM(INDIRECT("'"&$C32&"'!D90:D93")),"")) | N32: =IF(OR($J32="",$J32="no tab yet",$J32="tab empty"),"",IFERROR(INDIRECT("'"&$C32&"'!D94")+0,"")) | O32: =IF(OR($J32="",$J32="no tab yet",$J32="tab empty"),"",IFERROR(INDIRECT("'"&$C32&"'!D95")+0,"")) | P32: =IF(OR($J32="",$J32="no tab yet",$J32="tab empty"),"",IFERROR(INDIRECT("'"&$C32&"'!D97"),"")) | Q32: =IF(OR($J32="",$J32="no tab yet",$J32="tab empty"),"",IFERROR(INDIRECT("'"&$C32&"'!D98")+0,"")) | R32: =IF(AND(ISNUMBER(H32),ISNUMBER(Q32)),H32*Q32,"") | S32: =IFERROR(INDIRECT("'"&$C32&"'!D86")+0,"") | T32: =IFERROR(INDIRECT("'"&$C32&"'!D102")+0,"") | Y32: =IFERROR(INDIRECT("'"&$C32&"'!D82")+0,"") | Z32: =IFERROR(INDIRECT("'"&$C32&"'!D84")+0,"") | AA32: =IFERROR(INDIRECT("'"&$C32&"'!D89")+INDIRECT("'"&$C32&"'!D94"),"")
J33: =IF($C33="","",IF(ISERROR(INDIRECT("'"&$C33&"'!C1")),"no tab yet",IF(N(Y33)+N(AA33)=0,"tab empty",IF(N(T33)>0,"check inputs","costed")))) | K33: =IF(OR($J33="",$J33="no tab yet",$J33="tab empty"),"",IFERROR(INDIRECT("'"&$C33&"'!D87")+INDIRECT("'"&$C33&"'!D88"),"")) | L33: =IF(OR($J33="",$J33="no tab yet",$J33="tab empty"),"",IFERROR(INDIRECT("'"&$C33&"'!D89")+0,"")) | M33: =IF(OR($J33="",$J33="no tab yet",$J33="tab empty"),"",IFERROR(SUM(INDIRECT("'"&$C33&"'!D90:D93")),"")) | N33: =IF(OR($J33="",$J33="no tab yet",$J33="tab empty"),"",IFERROR(INDIRECT("'"&$C33&"'!D94")+0,"")) | O33: =IF(OR($J33="",$J33="no tab yet",$J33="tab empty"),"",IFERROR(INDIRECT("'"&$C33&"'!D95")+0,"")) | P33: =IF(OR($J33="",$J33="no tab yet",$J33="tab empty"),"",IFERROR(INDIRECT("'"&$C33&"'!D97"),"")) | Q33: =IF(OR($J33="",$J33="no tab yet",$J33="tab empty"),"",IFERROR(INDIRECT("'"&$C33&"'!D98")+0,"")) | R33: =IF(AND(ISNUMBER(H33),ISNUMBER(Q33)),H33*Q33,"") | S33: =IFERROR(INDIRECT("'"&$C33&"'!D86")+0,"") | T33: =IFERROR(INDIRECT("'"&$C33&"'!D102")+0,"") | Y33: =IFERROR(INDIRECT("'"&$C33&"'!D82")+0,"") | Z33: =IFERROR(INDIRECT("'"&$C33&"'!D84")+0,"") | AA33: =IFERROR(INDIRECT("'"&$C33&"'!D89")+INDIRECT("'"&$C33&"'!D94"),"")
J34: =IF($C34="","",IF(ISERROR(INDIRECT("'"&$C34&"'!C1")),"no tab yet",IF(N(Y34)+N(AA34)=0,"tab empty",IF(N(T34)>0,"check inputs","costed")))) | K34: =IF(OR($J34="",$J34="no tab yet",$J34="tab empty"),"",IFERROR(INDIRECT("'"&$C34&"'!D87")+INDIRECT("'"&$C34&"'!D88"),"")) | L34: =IF(OR($J34="",$J34="no tab yet",$J34="tab empty"),"",IFERROR(INDIRECT("'"&$C34&"'!D89")+0,"")) | M34: =IF(OR($J34="",$J34="no tab yet",$J34="tab empty"),"",IFERROR(SUM(INDIRECT("'"&$C34&"'!D90:D93")),"")) | N34: =IF(OR($J34="",$J34="no tab yet",$J34="tab empty"),"",IFERROR(INDIRECT("'"&$C34&"'!D94")+0,"")) | O34: =IF(OR($J34="",$J34="no tab yet",$J34="tab empty"),"",IFERROR(INDIRECT("'"&$C34&"'!D95")+0,"")) | P34: =IF(OR($J34="",$J34="no tab yet",$J34="tab empty"),"",IFERROR(INDIRECT("'"&$C34&"'!D97"),"")) | Q34: =IF(OR($J34="",$J34="no tab yet",$J34="tab empty"),"",IFERROR(INDIRECT("'"&$C34&"'!D98")+0,"")) | R34: =IF(AND(ISNUMBER(H34),ISNUMBER(Q34)),H34*Q34,"") | S34: =IFERROR(INDIRECT("'"&$C34&"'!D86")+0,"") | T34: =IFERROR(INDIRECT("'"&$C34&"'!D102")+0,"") | Y34: =IFERROR(INDIRECT("'"&$C34&"'!D82")+0,"") | Z34: =IFERROR(INDIRECT("'"&$C34&"'!D84")+0,"") | AA34: =IFERROR(INDIRECT("'"&$C34&"'!D89")+INDIRECT("'"&$C34&"'!D94"),"")
J35: =IF($C35="","",IF(ISERROR(INDIRECT("'"&$C35&"'!C1")),"no tab yet",IF(N(Y35)+N(AA35)=0,"tab empty",IF(N(T35)>0,"check inputs","costed")))) | K35: =IF(OR($J35="",$J35="no tab yet",$J35="tab empty"),"",IFERROR(INDIRECT("'"&$C35&"'!D87")+INDIRECT("'"&$C35&"'!D88"),"")) | L35: =IF(OR($J35="",$J35="no tab yet",$J35="tab empty"),"",IFERROR(INDIRECT("'"&$C35&"'!D89")+0,"")) | M35: =IF(OR($J35="",$J35="no tab yet",$J35="tab empty"),"",IFERROR(SUM(INDIRECT("'"&$C35&"'!D90:D93")),"")) | N35: =IF(OR($J35="",$J35="no tab yet",$J35="tab empty"),"",IFERROR(INDIRECT("'"&$C35&"'!D94")+0,"")) | O35: =IF(OR($J35="",$J35="no tab yet",$J35="tab empty"),"",IFERROR(INDIRECT("'"&$C35&"'!D95")+0,"")) | P35: =IF(OR($J35="",$J35="no tab yet",$J35="tab empty"),"",IFERROR(INDIRECT("'"&$C35&"'!D97"),"")) | Q35: =IF(OR($J35="",$J35="no tab yet",$J35="tab empty"),"",IFERROR(INDIRECT("'"&$C35&"'!D98")+0,"")) | R35: =IF(AND(ISNUMBER(H35),ISNUMBER(Q35)),H35*Q35,"") | S35: =IFERROR(INDIRECT("'"&$C35&"'!D86")+0,"") | T35: =IFERROR(INDIRECT("'"&$C35&"'!D102")+0,"") | Y35: =IFERROR(INDIRECT("'"&$C35&"'!D82")+0,"") | Z35: =IFERROR(INDIRECT("'"&$C35&"'!D84")+0,"") | AA35: =IFERROR(INDIRECT("'"&$C35&"'!D89")+INDIRECT("'"&$C35&"'!D94"),"")
J36: =IF($C36="","",IF(ISERROR(INDIRECT("'"&$C36&"'!C1")),"no tab yet",IF(N(Y36)+N(AA36)=0,"tab empty",IF(N(T36)>0,"check inputs","costed")))) | K36: =IF(OR($J36="",$J36="no tab yet",$J36="tab empty"),"",IFERROR(INDIRECT("'"&$C36&"'!D87")+INDIRECT("'"&$C36&"'!D88"),"")) | L36: =IF(OR($J36="",$J36="no tab yet",$J36="tab empty"),"",IFERROR(INDIRECT("'"&$C36&"'!D89")+0,"")) | M36: =IF(OR($J36="",$J36="no tab yet",$J36="tab empty"),"",IFERROR(SUM(INDIRECT("'"&$C36&"'!D90:D93")),"")) | N36: =IF(OR($J36="",$J36="no tab yet",$J36="tab empty"),"",IFERROR(INDIRECT("'"&$C36&"'!D94")+0,"")) | O36: =IF(OR($J36="",$J36="no tab yet",$J36="tab empty"),"",IFERROR(INDIRECT("'"&$C36&"'!D95")+0,"")) | P36: =IF(OR($J36="",$J36="no tab yet",$J36="tab empty"),"",IFERROR(INDIRECT("'"&$C36&"'!D97"),"")) | Q36: =IF(OR($J36="",$J36="no tab yet",$J36="tab empty"),"",IFERROR(INDIRECT("'"&$C36&"'!D98")+0,"")) | R36: =IF(AND(ISNUMBER(H36),ISNUMBER(Q36)),H36*Q36,"") | S36: =IFERROR(INDIRECT("'"&$C36&"'!D86")+0,"") | T36: =IFERROR(INDIRECT("'"&$C36&"'!D102")+0,"") | Y36: =IFERROR(INDIRECT("'"&$C36&"'!D82")+0,"") | Z36: =IFERROR(INDIRECT("'"&$C36&"'!D84")+0,"") | AA36: =IFERROR(INDIRECT("'"&$C36&"'!D89")+INDIRECT("'"&$C36&"'!D94"),"")
J37: =IF($C37="","",IF(ISERROR(INDIRECT("'"&$C37&"'!C1")),"no tab yet",IF(N(Y37)+N(AA37)=0,"tab empty",IF(N(T37)>0,"check inputs","costed")))) | K37: =IF(OR($J37="",$J37="no tab yet",$J37="tab empty"),"",IFERROR(INDIRECT("'"&$C37&"'!D87")+INDIRECT("'"&$C37&"'!D88"),"")) | L37: =IF(OR($J37="",$J37="no tab yet",$J37="tab empty"),"",IFERROR(INDIRECT("'"&$C37&"'!D89")+0,"")) | M37: =IF(OR($J37="",$J37="no tab yet",$J37="tab empty"),"",IFERROR(SUM(INDIRECT("'"&$C37&"'!D90:D93")),"")) | N37: =IF(OR($J37="",$J37="no tab yet",$J37="tab empty"),"",IFERROR(INDIRECT("'"&$C37&"'!D94")+0,"")) | O37: =IF(OR($J37="",$J37="no tab yet",$J37="tab empty"),"",IFERROR(INDIRECT("'"&$C37&"'!D95")+0,"")) | P37: =IF(OR($J37="",$J37="no tab yet",$J37="tab empty"),"",IFERROR(INDIRECT("'"&$C37&"'!D97"),"")) | Q37: =IF(OR($J37="",$J37="no tab yet",$J37="tab empty"),"",IFERROR(INDIRECT("'"&$C37&"'!D98")+0,"")) | R37: =IF(AND(ISNUMBER(H37),ISNUMBER(Q37)),H37*Q37,"") | S37: =IFERROR(INDIRECT("'"&$C37&"'!D86")+0,"") | T37: =IFERROR(INDIRECT("'"&$C37&"'!D102")+0,"") | Y37: =IFERROR(INDIRECT("'"&$C37&"'!D82")+0,"") | Z37: =IFERROR(INDIRECT("'"&$C37&"'!D84")+0,"") | AA37: =IFERROR(INDIRECT("'"&$C37&"'!D89")+INDIRECT("'"&$C37&"'!D94"),"")
J38: =IF($C38="","",IF(ISERROR(INDIRECT("'"&$C38&"'!C1")),"no tab yet",IF(N(Y38)+N(AA38)=0,"tab empty",IF(N(T38)>0,"check inputs","costed")))) | K38: =IF(OR($J38="",$J38="no tab yet",$J38="tab empty"),"",IFERROR(INDIRECT("'"&$C38&"'!D87")+INDIRECT("'"&$C38&"'!D88"),"")) | L38: =IF(OR($J38="",$J38="no tab yet",$J38="tab empty"),"",IFERROR(INDIRECT("'"&$C38&"'!D89")+0,"")) | M38: =IF(OR($J38="",$J38="no tab yet",$J38="tab empty"),"",IFERROR(SUM(INDIRECT("'"&$C38&"'!D90:D93")),"")) | N38: =IF(OR($J38="",$J38="no tab yet",$J38="tab empty"),"",IFERROR(INDIRECT("'"&$C38&"'!D94")+0,"")) | O38: =IF(OR($J38="",$J38="no tab yet",$J38="tab empty"),"",IFERROR(INDIRECT("'"&$C38&"'!D95")+0,"")) | P38: =IF(OR($J38="",$J38="no tab yet",$J38="tab empty"),"",IFERROR(INDIRECT("'"&$C38&"'!D97"),"")) | Q38: =IF(OR($J38="",$J38="no tab yet",$J38="tab empty"),"",IFERROR(INDIRECT("'"&$C38&"'!D98")+0,"")) | R38: =IF(AND(ISNUMBER(H38),ISNUMBER(Q38)),H38*Q38,"") | S38: =IFERROR(INDIRECT("'"&$C38&"'!D86")+0,"") | T38: =IFERROR(INDIRECT("'"&$C38&"'!D102")+0,"") | Y38: =IFERROR(INDIRECT("'"&$C38&"'!D82")+0,"") | Z38: =IFERROR(INDIRECT("'"&$C38&"'!D84")+0,"") | AA38: =IFERROR(INDIRECT("'"&$C38&"'!D89")+INDIRECT("'"&$C38&"'!D94"),"")
J39: =IF($C39="","",IF(ISERROR(INDIRECT("'"&$C39&"'!C1")),"no tab yet",IF(N(Y39)+N(AA39)=0,"tab empty",IF(N(T39)>0,"check inputs","costed")))) | K39: =IF(OR($J39="",$J39="no tab yet",$J39="tab empty"),"",IFERROR(INDIRECT("'"&$C39&"'!D87")+INDIRECT("'"&$C39&"'!D88"),"")) | L39: =IF(OR($J39="",$J39="no tab yet",$J39="tab empty"),"",IFERROR(INDIRECT("'"&$C39&"'!D89")+0,"")) | M39: =IF(OR($J39="",$J39="no tab yet",$J39="tab empty"),"",IFERROR(SUM(INDIRECT("'"&$C39&"'!D90:D93")),"")) | N39: =IF(OR($J39="",$J39="no tab yet",$J39="tab empty"),"",IFERROR(INDIRECT("'"&$C39&"'!D94")+0,"")) | O39: =IF(OR($J39="",$J39="no tab yet",$J39="tab empty"),"",IFERROR(INDIRECT("'"&$C39&"'!D95")+0,"")) | P39: =IF(OR($J39="",$J39="no tab yet",$J39="tab empty"),"",IFERROR(INDIRECT("'"&$C39&"'!D97"),"")) | Q39: =IF(OR($J39="",$J39="no tab yet",$J39="tab empty"),"",IFERROR(INDIRECT("'"&$C39&"'!D98")+0,"")) | R39: =IF(AND(ISNUMBER(H39),ISNUMBER(Q39)),H39*Q39,"") | S39: =IFERROR(INDIRECT("'"&$C39&"'!D86")+0,"") | T39: =IFERROR(INDIRECT("'"&$C39&"'!D102")+0,"") | Y39: =IFERROR(INDIRECT("'"&$C39&"'!D82")+0,"") | Z39: =IFERROR(INDIRECT("'"&$C39&"'!D84")+0,"") | AA39: =IFERROR(INDIRECT("'"&$C39&"'!D89")+INDIRECT("'"&$C39&"'!D94"),"")
J40: =IF($C40="","",IF(ISERROR(INDIRECT("'"&$C40&"'!C1")),"no tab yet",IF(N(Y40)+N(AA40)=0,"tab empty",IF(N(T40)>0,"check inputs","costed")))) | K40: =IF(OR($J40="",$J40="no tab yet",$J40="tab empty"),"",IFERROR(INDIRECT("'"&$C40&"'!D87")+INDIRECT("'"&$C40&"'!D88"),"")) | L40: =IF(OR($J40="",$J40="no tab yet",$J40="tab empty"),"",IFERROR(INDIRECT("'"&$C40&"'!D89")+0,"")) | M40: =IF(OR($J40="",$J40="no tab yet",$J40="tab empty"),"",IFERROR(SUM(INDIRECT("'"&$C40&"'!D90:D93")),"")) | N40: =IF(OR($J40="",$J40="no tab yet",$J40="tab empty"),"",IFERROR(INDIRECT("'"&$C40&"'!D94")+0,"")) | O40: =IF(OR($J40="",$J40="no tab yet",$J40="tab empty"),"",IFERROR(INDIRECT("'"&$C40&"'!D95")+0,"")) | P40: =IF(OR($J40="",$J40="no tab yet",$J40="tab empty"),"",IFERROR(INDIRECT("'"&$C40&"'!D97"),"")) | Q40: =IF(OR($J40="",$J40="no tab yet",$J40="tab empty"),"",IFERROR(INDIRECT("'"&$C40&"'!D98")+0,"")) | R40: =IF(AND(ISNUMBER(H40),ISNUMBER(Q40)),H40*Q40,"") | S40: =IFERROR(INDIRECT("'"&$C40&"'!D86")+0,"") | T40: =IFERROR(INDIRECT("'"&$C40&"'!D102")+0,"") | Y40: =IFERROR(INDIRECT("'"&$C40&"'!D82")+0,"") | Z40: =IFERROR(INDIRECT("'"&$C40&"'!D84")+0,"") | AA40: =IFERROR(INDIRECT("'"&$C40&"'!D89")+INDIRECT("'"&$C40&"'!D94"),"")
J41: =IF($C41="","",IF(ISERROR(INDIRECT("'"&$C41&"'!C1")),"no tab yet",IF(N(Y41)+N(AA41)=0,"tab empty",IF(N(T41)>0,"check inputs","costed")))) | K41: =IF(OR($J41="",$J41="no tab yet",$J41="tab empty"),"",IFERROR(INDIRECT("'"&$C41&"'!D87")+INDIRECT("'"&$C41&"'!D88"),"")) | L41: =IF(OR($J41="",$J41="no tab yet",$J41="tab empty"),"",IFERROR(INDIRECT("'"&$C41&"'!D89")+0,"")) | M41: =IF(OR($J41="",$J41="no tab yet",$J41="tab empty"),"",IFERROR(SUM(INDIRECT("'"&$C41&"'!D90:D93")),"")) | N41: =IF(OR($J41="",$J41="no tab yet",$J41="tab empty"),"",IFERROR(INDIRECT("'"&$C41&"'!D94")+0,"")) | O41: =IF(OR($J41="",$J41="no tab yet",$J41="tab empty"),"",IFERROR(INDIRECT("'"&$C41&"'!D95")+0,"")) | P41: =IF(OR($J41="",$J41="no tab yet",$J41="tab empty"),"",IFERROR(INDIRECT("'"&$C41&"'!D97"),"")) | Q41: =IF(OR($J41="",$J41="no tab yet",$J41="tab empty"),"",IFERROR(INDIRECT("'"&$C41&"'!D98")+0,"")) | R41: =IF(AND(ISNUMBER(H41),ISNUMBER(Q41)),H41*Q41,"") | S41: =IFERROR(INDIRECT("'"&$C41&"'!D86")+0,"") | T41: =IFERROR(INDIRECT("'"&$C41&"'!D102")+0,"") | Y41: =IFERROR(INDIRECT("'"&$C41&"'!D82")+0,"") | Z41: =IFERROR(INDIRECT("'"&$C41&"'!D84")+0,"") | AA41: =IFERROR(INDIRECT("'"&$C41&"'!D89")+INDIRECT("'"&$C41&"'!D94"),"")
... J53: =IF($C53="","",IF(ISERROR(INDIRECT("'"&$C53&"'!C1")),"no tab yet",IF(N(Y53)+N(AA53)=0,"tab empty",IF(N(T53)>0,"check inputs","costed")))) | K53: =IF(OR($J53="",$J53="no tab yet",$J53="tab empty"),"",IFERROR(INDIRECT("'"&$C53&"'!D87")+INDIRECT("'"&$C53&"'!D88"),"")) | L53: =IF(OR($J53="",$J53="no tab yet",$J53="tab empty"),"",IFERROR(INDIRECT("'"&$C53&"'!D89")+0,"")) | M53: =IF(OR($J53="",$J53="no tab yet",$J53="tab empty"),"",IFERROR(SUM(INDIRECT("'"&$C53&"'!D90:D93")),"")) | N53: =IF(OR($J53="",$J53="no tab yet",$J53="tab empty"),"",IFERROR(INDIRECT("'"&$C53&"'!D94")+0,"")) | O53: =IF(OR($J53="",$J53="no tab yet",$J53="tab empty"),"",IFERROR(INDIRECT("'"&$C53&"'!D95")+0,"")) | P53: =IF(OR($J53="",$J53="no tab yet",$J53="tab empty"),"",IFERROR(INDIRECT("'"&$C53&"'!D97"),"")) | Q53: =IF(OR($J53="",$J53="no tab yet",$J53="tab empty"),"",IFERROR(INDIRECT("'"&$C53&"'!D98")+0,"")) | R53: =IF(AND(ISNUMBER(H53),ISNUMBER(Q53)),H53*Q53,"") | S53: =IFERROR(INDIRECT("'"&$C53&"'!D86")+0,"") | T53: =IFERROR(INDIRECT("'"&$C53&"'!D102")+0,"") | Y53: =IFERROR(INDIRECT("'"&$C53&"'!D82")+0,"") | Z53: =IFERROR(INDIRECT("'"&$C53&"'!D84")+0,"") | AA53: =IFERROR(INDIRECT("'"&$C53&"'!D89")+INDIRECT("'"&$C53&"'!D94"),"")
J54: =COUNTIF(J5:J53,"costed")&" costed / "&COUNTA(C5:C53)&" items" | Q54: =SUM(Q5:Q53) | R54: =SUM(R5:R53) | S54: =SUM(S5:S53) | Y54: =SUM(Y5:Y53) | Z54: =SUM(Z5:Z53)
J57: COSTED | Q57: UNIT COST IDR, sum | R57: ORDER TOTAL IDR | S57: CARTON m³, sum | Y57: SOLID WOOD m³, sum | Z57: FINISHING m², sum
J58: =COUNTIFS($B$5:$B$53,$D58,$J$5:$J$53,"costed") | Q58: =SUMIF($B$5:$B$53,$D58,Q$5:Q$53) | R58: =SUMIF($B$5:$B$53,$D58,R$5:R$53) | S58: =SUMIF($B$5:$B$53,$D58,S$5:S$53) | Y58: =SUMIF($B$5:$B$53,$D58,Y$5:Y$53) | Z58: =SUMIF($B$5:$B$53,$D58,Z$5:Z$53)
J59: =COUNTIFS($B$5:$B$53,$D59,$J$5:$J$53,"costed") | Q59: =SUMIF($B$5:$B$53,$D59,Q$5:Q$53) | R59: =SUMIF($B$5:$B$53,$D59,R$5:R$53) | S59: =SUMIF($B$5:$B$53,$D59,S$5:S$53) | Y59: =SUMIF($B$5:$B$53,$D59,Y$5:Y$53) | Z59: =SUMIF($B$5:$B$53,$D59,Z$5:Z$53)
J60: =COUNTIFS($B$5:$B$53,$D60,$J$5:$J$53,"costed") | Q60: =SUMIF($B$5:$B$53,$D60,Q$5:Q$53) | R60: =SUMIF($B$5:$B$53,$D60,R$5:R$53) | S60: =SUMIF($B$5:$B$53,$D60,S$5:S$53) | Y60: =SUMIF($B$5:$B$53,$D60,Y$5:Y$53) | Z60: =SUMIF($B$5:$B$53,$D60,Z$5:Z$53)

Sheet TEMPLATE
A1: ITEM CODE | D1: OVERALL L mm | G1: {=IFERROR(IF(INDEX(ITEMS!$E$5:$E$120,MATCH($C$1,ITEMS!$C$5:$C$120,0))="","",INDEX(ITEMS!$E$5:$E$120,MATCH($C$1,ITEMS!$C$5:$C$120,0))),"")} | L1: =IF(G6="","photo",_xludf.IMAGE(G6))
A2: ITEM NAME | C2: {=IFERROR(IF(INDEX(ITEMS!$D$5:$D$120,MATCH($C$1,ITEMS!$C$5:$C$120,0))="","",INDEX(ITEMS!$D$5:$D$120,MATCH($C$1,ITEMS!$C$5:$C$120,0))),"")} | D2: OVERALL W mm | G2: {=IFERROR(IF(INDEX(ITEMS!$F$5:$F$120,MATCH($C$1,ITEMS!$C$5:$C$120,0))="","",INDEX(ITEMS!$F$5:$F$120,MATCH($C$1,ITEMS!$C$5:$C$120,0))),"")}
A3: COLLECTION / ROOM | C3: {=IFERROR(INDEX(ITEMS!$B$5:$B$120,MATCH($C$1,ITEMS!$C$5:$C$120,0))&" / "&INDEX(ITEMS!$W$5:$W$120,MATCH($C$1,ITEMS!$C$5:$C$120,0)),"")} | D3: OVERALL H mm | G3: {=IFERROR(IF(INDEX(ITEMS!$G$5:$G$120,MATCH($C$1,ITEMS!$C$5:$C$120,0))="","",INDEX(ITEMS!$G$5:$G$120,MATCH($C$1,ITEMS!$C$5:$C$120,0))),"")}
A4: ORDER QTY | C4: {=IFERROR(IF(INDEX(ITEMS!$H$5:$H$120,MATCH($C$1,ITEMS!$C$5:$C$120,0))="","",INDEX(ITEMS!$H$5:$H$120,MATCH($C$1,ITEMS!$C$5:$C$120,0))),"")} | D4: DRAWING LINK | G4: {=IFERROR(IF(INDEX(ITEMS!$I$5:$I$120,MATCH($C$1,ITEMS!$C$5:$C$120,0))="","",INDEX(ITEMS!$I$5:$I$120,MATCH($C$1,ITEMS!$C$5:$C$120,0))),"")}
A5: FINISH RECIPE | D5: SPEC LINK | G5: {=IFERROR(IF(INDEX(ITEMS!$V$5:$V$120,MATCH($C$1,ITEMS!$C$5:$C$120,0))="","",INDEX(ITEMS!$V$5:$V$120,MATCH($C$1,ITEMS!$C$5:$C$120,0))),"")}
A6: FLATPACK? (Y/N) | D6: PHOTO LINK
A7: NOTES | C7: {=IFERROR(IF(INDEX(ITEMS!$X$5:$X$120,MATCH($C$1,ITEMS!$C$5:$C$120,0))="","",INDEX(ITEMS!$X$5:$X$120,MATCH($C$1,ITEMS!$C$5:$C$120,0))),"")} | D7: REVISION / DATE
A9: PACKING: assembled = leave boxes blank (system uses overall size + 40 mm as 1 carton). Flatpack = one row per box.
A10: BOX | B10: CONTENTS | D10: L mm | E10: W mm | F10: H mm | G10: QTY | H10: CARTON L | I10: CARTON W | J10: CARTON H | L10: m² 6 sides (calc) | M10: m³ (calc)
A11: 1 | H11: =IF(D11="","",D11+LISTS!$F$9) | I11: =IF(E11="","",E11+LISTS!$F$9) | J11: =IF(F11="","",F11+LISTS!$F$9) | L11: =IF(H11="","",2*(H11*I11+H11*J11+I11*J11)/1000000*IF(G11="",1,G11)) | M11: =IF(H11="","",H11*I11*J11/1000000000*IF(G11="",1,G11))
A12: 2 | H12: =IF(D12="","",D12+LISTS!$F$9) | I12: =IF(E12="","",E12+LISTS!$F$9) | J12: =IF(F12="","",F12+LISTS!$F$9) | L12: =IF(H12="","",2*(H12*I12+H12*J12+I12*J12)/1000000*IF(G12="",1,G12)) | M12: =IF(H12="","",H12*I12*J12/1000000000*IF(G12="",1,G12))
A13: 3 | H13: =IF(D13="","",D13+LISTS!$F$9) | I13: =IF(E13="","",E13+LISTS!$F$9) | J13: =IF(F13="","",F13+LISTS!$F$9) | L13: =IF(H13="","",2*(H13*I13+H13*J13+I13*J13)/1000000*IF(G13="",1,G13)) | M13: =IF(H13="","",H13*I13*J13/1000000000*IF(G13="",1,G13))
A14: 4 | H14: =IF(D14="","",D14+LISTS!$F$9) | I14: =IF(E14="","",E14+LISTS!$F$9) | J14: =IF(F14="","",F14+LISTS!$F$9) | L14: =IF(H14="","",2*(H14*I14+H14*J14+I14*J14)/1000000*IF(G14="",1,G14)) | M14: =IF(H14="","",H14*I14*J14/1000000000*IF(G14="",1,G14))
A15: TOTAL | G15: =IF(D11="",1,SUM(G11:G14)+COUNTIFS(D11:D14,"<>",G11:G14,"")) | H15: cartons | L15: =IF(D11="",IF(OR(G1="",G2="",G3=""),0,2*((G1+LISTS!$F$9)*(G2+LISTS!$F$9)+(G1+LISTS!$F$9)*(G3+LISTS!$F$9)+(G2+LISTS!$F$9)*(G3+LISTS!$F$9))/1000000),SUM(L11:L14)) | M15: =IF(D11="",IF(OR(G1="",G2="",G3=""),0,(G1+LISTS!$F$9)*(G2+LISTS!$F$9)*(G3+LISTS!$F$9)/1000000000),SUM(M11:M14))
A16: SOLID WOOD: one line per component, mm, qty per ONE item
A17: NO | B17: MATERIAL | C17: LABEL | D17: COMPONENT | E17: L mm | F17: W mm | G17: T mm | H17: QTY | I17: EXPOSED Y/N | J17: CURVED Y/N | K17: TIER OVERRIDE | L17: NOTE | M17: VOL m³ (calc) | N17: FACE m² (calc) | O17: AUTO TIER (calc) | R17: CHECK (calc) | S17: RATE (system) | T17: COST IDR (system) | U17: COST USD (system)
A18: 1 | M18: =IF(OR(E18="",F18="",G18=""),"",E18*F18*G18/1000000000*IF(H18="",1,H18)) | N18: =IF(OR(E18="",F18=""),"",E18*F18/1000000*IF(H18="",1,H18)) | O18: =IF(E18="","",IF(K18<>"",K18,IF(AND(E18*F18*G18/1000000000<LISTS!$F$4,MAX(E18,F18,G18)<LISTS!$F$5),"D",IF(I18="N","C",IF(J18="Y","A-CURVED",IF(AND(MEDIAN(E18,F18,G18)<=LISTS!$F$10,MAX(E18,F18,G18)<=LISTS!$F$11),"B",IF(MAX(E18,F18,G18)>=LISTS!$F$3,"A","B"))))))) | R18: =IF(E18="","",IF(B18="","material?",IF(OR(F18="",G18=""),"size?",IF(I18="","exposed Y/N?",IF(H18="","qty?",IF(B18="OTHER","OTHER: no rate, price it under hardware","OK")))))) | S18: {=IF(OR(O18="",M18=""),"",IF(B18="MERANTI",RATES!$C$45,IFERROR(INDEX(RATES!$C:$C,MATCH(B18&"_"&SUBSTITUTE(O18,"-CURVED","C"),RATES!$A:$A,0)),"rate?")))} | T18: =IF(ISNUMBER(S18),M18*S18,"")
A19: 2 | M19: =IF(OR(E19="",F19="",G19=""),"",E19*F19*G19/1000000000*IF(H19="",1,H19)) | N19: =IF(OR(E19="",F19=""),"",E19*F19/1000000*IF(H19="",1,H19)) | O19: =IF(E19="","",IF(K19<>"",K19,IF(AND(E19*F19*G19/1000000000<LISTS!$F$4,MAX(E19,F19,G19)<LISTS!$F$5),"D",IF(I19="N","C",IF(J19="Y","A-CURVED",IF(AND(MEDIAN(E19,F19,G19)<=LISTS!$F$10,MAX(E19,F19,G19)<=LISTS!$F$11),"B",IF(MAX(E19,F19,G19)>=LISTS!$F$3,"A","B"))))))) | R19: =IF(E19="","",IF(B19="","material?",IF(OR(F19="",G19=""),"size?",IF(I19="","exposed Y/N?",IF(H19="","qty?",IF(B19="OTHER","OTHER: no rate, price it under hardware","OK")))))) | S19: {=IF(OR(O19="",M19=""),"",IF(B19="MERANTI",RATES!$C$45,IFERROR(INDEX(RATES!$C:$C,MATCH(B19&"_"&SUBSTITUTE(O19,"-CURVED","C"),RATES!$A:$A,0)),"rate?")))} | T19: =IF(ISNUMBER(S19),M19*S19,"")
A20: 3 | M20: =IF(OR(E20="",F20="",G20=""),"",E20*F20*G20/1000000000*IF(H20="",1,H20)) | N20: =IF(OR(E20="",F20=""),"",E20*F20/1000000*IF(H20="",1,H20)) | O20: =IF(E20="","",IF(K20<>"",K20,IF(AND(E20*F20*G20/1000000000<LISTS!$F$4,MAX(E20,F20,G20)<LISTS!$F$5),"D",IF(I20="N","C",IF(J20="Y","A-CURVED",IF(AND(MEDIAN(E20,F20,G20)<=LISTS!$F$10,MAX(E20,F20,G20)<=LISTS!$F$11),"B",IF(MAX(E20,F20,G20)>=LISTS!$F$3,"A","B"))))))) | R20: =IF(E20="","",IF(B20="","material?",IF(OR(F20="",G20=""),"size?",IF(I20="","exposed Y/N?",IF(H20="","qty?",IF(B20="OTHER","OTHER: no rate, price it under hardware","OK")))))) | S20: {=IF(OR(O20="",M20=""),"",IF(B20="MERANTI",RATES!$C$45,IFERROR(INDEX(RATES!$C:$C,MATCH(B20&"_"&SUBSTITUTE(O20,"-CURVED","C"),RATES!$A:$A,0)),"rate?")))} | T20: =IF(ISNUMBER(S20),M20*S20,"")
A21: 4 | M21: =IF(OR(E21="",F21="",G21=""),"",E21*F21*G21/1000000000*IF(H21="",1,H21)) | N21: =IF(OR(E21="",F21=""),"",E21*F21/1000000*IF(H21="",1,H21)) | O21: =IF(E21="","",IF(K21<>"",K21,IF(AND(E21*F21*G21/1000000000<LISTS!$F$4,MAX(E21,F21,G21)<LISTS!$F$5),"D",IF(I21="N","C",IF(J21="Y","A-CURVED",IF(AND(MEDIAN(E21,F21,G21)<=LISTS!$F$10,MAX(E21,F21,G21)<=LISTS!$F$11),"B",IF(MAX(E21,F21,G21)>=LISTS!$F$3,"A","B"))))))) | R21: =IF(E21="","",IF(B21="","material?",IF(OR(F21="",G21=""),"size?",IF(I21="","exposed Y/N?",IF(H21="","qty?",IF(B21="OTHER","OTHER: no rate, price it under hardware","OK")))))) | S21: {=IF(OR(O21="",M21=""),"",IF(B21="MERANTI",RATES!$C$45,IFERROR(INDEX(RATES!$C:$C,MATCH(B21&"_"&SUBSTITUTE(O21,"-CURVED","C"),RATES!$A:$A,0)),"rate?")))} | T21: =IF(ISNUMBER(S21),M21*S21,"")
A22: 5 | M22: =IF(OR(E22="",F22="",G22=""),"",E22*F22*G22/1000000000*IF(H22="",1,H22)) | N22: =IF(OR(E22="",F22=""),"",E22*F22/1000000*IF(H22="",1,H22)) | O22: =IF(E22="","",IF(K22<>"",K22,IF(AND(E22*F22*G22/1000000000<LISTS!$F$4,MAX(E22,F22,G22)<LISTS!$F$5),"D",IF(I22="N","C",IF(J22="Y","A-CURVED",IF(AND(MEDIAN(E22,F22,G22)<=LISTS!$F$10,MAX(E22,F22,G22)<=LISTS!$F$11),"B",IF(MAX(E22,F22,G22)>=LISTS!$F$3,"A","B"))))))) | R22: =IF(E22="","",IF(B22="","material?",IF(OR(F22="",G22=""),"size?",IF(I22="","exposed Y/N?",IF(H22="","qty?",IF(B22="OTHER","OTHER: no rate, price it under hardware","OK")))))) | S22: {=IF(OR(O22="",M22=""),"",IF(B22="MERANTI",RATES!$C$45,IFERROR(INDEX(RATES!$C:$C,MATCH(B22&"_"&SUBSTITUTE(O22,"-CURVED","C"),RATES!$A:$A,0)),"rate?")))} | T22: =IF(ISNUMBER(S22),M22*S22,"")
A23: 6 | M23: =IF(OR(E23="",F23="",G23=""),"",E23*F23*G23/1000000000*IF(H23="",1,H23)) | N23: =IF(OR(E23="",F23=""),"",E23*F23/1000000*IF(H23="",1,H23)) | O23: =IF(E23="","",IF(K23<>"",K23,IF(AND(E23*F23*G23/1000000000<LISTS!$F$4,MAX(E23,F23,G23)<LISTS!$F$5),"D",IF(I23="N","C",IF(J23="Y","A-CURVED",IF(AND(MEDIAN(E23,F23,G23)<=LISTS!$F$10,MAX(E23,F23,G23)<=LISTS!$F$11),"B",IF(MAX(E23,F23,G23)>=LISTS!$F$3,"A","B"))))))) | R23: =IF(E23="","",IF(B23="","material?",IF(OR(F23="",G23=""),"size?",IF(I23="","exposed Y/N?",IF(H23="","qty?",IF(B23="OTHER","OTHER: no rate, price it under hardware","OK")))))) | S23: {=IF(OR(O23="",M23=""),"",IF(B23="MERANTI",RATES!$C$45,IFERROR(INDEX(RATES!$C:$C,MATCH(B23&"_"&SUBSTITUTE(O23,"-CURVED","C"),RATES!$A:$A,0)),"rate?")))} | T23: =IF(ISNUMBER(S23),M23*S23,"")
A24: 7 | M24: =IF(OR(E24="",F24="",G24=""),"",E24*F24*G24/1000000000*IF(H24="",1,H24)) | N24: =IF(OR(E24="",F24=""),"",E24*F24/1000000*IF(H24="",1,H24)) | O24: =IF(E24="","",IF(K24<>"",K24,IF(AND(E24*F24*G24/1000000000<LISTS!$F$4,MAX(E24,F24,G24)<LISTS!$F$5),"D",IF(I24="N","C",IF(J24="Y","A-CURVED",IF(AND(MEDIAN(E24,F24,G24)<=LISTS!$F$10,MAX(E24,F24,G24)<=LISTS!$F$11),"B",IF(MAX(E24,F24,G24)>=LISTS!$F$3,"A","B"))))))) | R24: =IF(E24="","",IF(B24="","material?",IF(OR(F24="",G24=""),"size?",IF(I24="","exposed Y/N?",IF(H24="","qty?",IF(B24="OTHER","OTHER: no rate, price it under hardware","OK")))))) | S24: {=IF(OR(O24="",M24=""),"",IF(B24="MERANTI",RATES!$C$45,IFERROR(INDEX(RATES!$C:$C,MATCH(B24&"_"&SUBSTITUTE(O24,"-CURVED","C"),RATES!$A:$A,0)),"rate?")))} | T24: =IF(ISNUMBER(S24),M24*S24,"")
A25: 8 | M25: =IF(OR(E25="",F25="",G25=""),"",E25*F25*G25/1000000000*IF(H25="",1,H25)) | N25: =IF(OR(E25="",F25=""),"",E25*F25/1000000*IF(H25="",1,H25)) | O25: =IF(E25="","",IF(K25<>"",K25,IF(AND(E25*F25*G25/1000000000<LISTS!$F$4,MAX(E25,F25,G25)<LISTS!$F$5),"D",IF(I25="N","C",IF(J25="Y","A-CURVED",IF(AND(MEDIAN(E25,F25,G25)<=LISTS!$F$10,MAX(E25,F25,G25)<=LISTS!$F$11),"B",IF(MAX(E25,F25,G25)>=LISTS!$F$3,"A","B"))))))) | R25: =IF(E25="","",IF(B25="","material?",IF(OR(F25="",G25=""),"size?",IF(I25="","exposed Y/N?",IF(H25="","qty?",IF(B25="OTHER","OTHER: no rate, price it under hardware","OK")))))) | S25: {=IF(OR(O25="",M25=""),"",IF(B25="MERANTI",RATES!$C$45,IFERROR(INDEX(RATES!$C:$C,MATCH(B25&"_"&SUBSTITUTE(O25,"-CURVED","C"),RATES!$A:$A,0)),"rate?")))} | T25: =IF(ISNUMBER(S25),M25*S25,"")
A26: 9 | M26: =IF(OR(E26="",F26="",G26=""),"",E26*F26*G26/1000000000*IF(H26="",1,H26)) | N26: =IF(OR(E26="",F26=""),"",E26*F26/1000000*IF(H26="",1,H26)) | O26: =IF(E26="","",IF(K26<>"",K26,IF(AND(E26*F26*G26/1000000000<LISTS!$F$4,MAX(E26,F26,G26)<LISTS!$F$5),"D",IF(I26="N","C",IF(J26="Y","A-CURVED",IF(AND(MEDIAN(E26,F26,G26)<=LISTS!$F$10,MAX(E26,F26,G26)<=LISTS!$F$11),"B",IF(MAX(E26,F26,G26)>=LISTS!$F$3,"A","B"))))))) | R26: =IF(E26="","",IF(B26="","material?",IF(OR(F26="",G26=""),"size?",IF(I26="","exposed Y/N?",IF(H26="","qty?",IF(B26="OTHER","OTHER: no rate, price it under hardware","OK")))))) | S26: {=IF(OR(O26="",M26=""),"",IF(B26="MERANTI",RATES!$C$45,IFERROR(INDEX(RATES!$C:$C,MATCH(B26&"_"&SUBSTITUTE(O26,"-CURVED","C"),RATES!$A:$A,0)),"rate?")))} | T26: =IF(ISNUMBER(S26),M26*S26,"")
A27: 10 | M27: =IF(OR(E27="",F27="",G27=""),"",E27*F27*G27/1000000000*IF(H27="",1,H27)) | N27: =IF(OR(E27="",F27=""),"",E27*F27/1000000*IF(H27="",1,H27)) | O27: =IF(E27="","",IF(K27<>"",K27,IF(AND(E27*F27*G27/1000000000<LISTS!$F$4,MAX(E27,F27,G27)<LISTS!$F$5),"D",IF(I27="N","C",IF(J27="Y","A-CURVED",IF(AND(MEDIAN(E27,F27,G27)<=LISTS!$F$10,MAX(E27,F27,G27)<=LISTS!$F$11),"B",IF(MAX(E27,F27,G27)>=LISTS!$F$3,"A","B"))))))) | R27: =IF(E27="","",IF(B27="","material?",IF(OR(F27="",G27=""),"size?",IF(I27="","exposed Y/N?",IF(H27="","qty?",IF(B27="OTHER","OTHER: no rate, price it under hardware","OK")))))) | S27: {=IF(OR(O27="",M27=""),"",IF(B27="MERANTI",RATES!$C$45,IFERROR(INDEX(RATES!$C:$C,MATCH(B27&"_"&SUBSTITUTE(O27,"-CURVED","C"),RATES!$A:$A,0)),"rate?")))} | T27: =IF(ISNUMBER(S27),M27*S27,"")
A28: 11 | M28: =IF(OR(E28="",F28="",G28=""),"",E28*F28*G28/1000000000*IF(H28="",1,H28)) | N28: =IF(OR(E28="",F28=""),"",E28*F28/1000000*IF(H28="",1,H28)) | O28: =IF(E28="","",IF(K28<>"",K28,IF(AND(E28*F28*G28/1000000000<LISTS!$F$4,MAX(E28,F28,G28)<LISTS!$F$5),"D",IF(I28="N","C",IF(J28="Y","A-CURVED",IF(AND(MEDIAN(E28,F28,G28)<=LISTS!$F$10,MAX(E28,F28,G28)<=LISTS!$F$11),"B",IF(MAX(E28,F28,G28)>=LISTS!$F$3,"A","B"))))))) | R28: =IF(E28="","",IF(B28="","material?",IF(OR(F28="",G28=""),"size?",IF(I28="","exposed Y/N?",IF(H28="","qty?",IF(B28="OTHER","OTHER: no rate, price it under hardware","OK")))))) | S28: {=IF(OR(O28="",M28=""),"",IF(B28="MERANTI",RATES!$C$45,IFERROR(INDEX(RATES!$C:$C,MATCH(B28&"_"&SUBSTITUTE(O28,"-CURVED","C"),RATES!$A:$A,0)),"rate?")))} | T28: =IF(ISNUMBER(S28),M28*S28,"")
A29: 12 | M29: =IF(OR(E29="",F29="",G29=""),"",E29*F29*G29/1000000000*IF(H29="",1,H29)) | N29: =IF(OR(E29="",F29=""),"",E29*F29/1000000*IF(H29="",1,H29)) | O29: =IF(E29="","",IF(K29<>"",K29,IF(AND(E29*F29*G29/1000000000<LISTS!$F$4,MAX(E29,F29,G29)<LISTS!$F$5),"D",IF(I29="N","C",IF(J29="Y","A-CURVED",IF(AND(MEDIAN(E29,F29,G29)<=LISTS!$F$10,MAX(E29,F29,G29)<=LISTS!$F$11),"B",IF(MAX(E29,F29,G29)>=LISTS!$F$3,"A","B"))))))) | R29: =IF(E29="","",IF(B29="","material?",IF(OR(F29="",G29=""),"size?",IF(I29="","exposed Y/N?",IF(H29="","qty?",IF(B29="OTHER","OTHER: no rate, price it under hardware","OK")))))) | S29: {=IF(OR(O29="",M29=""),"",IF(B29="MERANTI",RATES!$C$45,IFERROR(INDEX(RATES!$C:$C,MATCH(B29&"_"&SUBSTITUTE(O29,"-CURVED","C"),RATES!$A:$A,0)),"rate?")))} | T29: =IF(ISNUMBER(S29),M29*S29,"")
... A32: 15 | M32: =IF(OR(E32="",F32="",G32=""),"",E32*F32*G32/1000000000*IF(H32="",1,H32)) | N32: =IF(OR(E32="",F32=""),"",E32*F32/1000000*IF(H32="",1,H32)) | O32: =IF(E32="","",IF(K32<>"",K32,IF(AND(E32*F32*G32/1000000000<LISTS!$F$4,MAX(E32,F32,G32)<LISTS!$F$5),"D",IF(I32="N","C",IF(J32="Y","A-CURVED",IF(AND(MEDIAN(E32,F32,G32)<=LISTS!$F$10,MAX(E32,F32,G32)<=LISTS!$F$11),"B",IF(MAX(E32,F32,G32)>=LISTS!$F$3,"A","B"))))))) | R32: =IF(E32="","",IF(B32="","material?",IF(OR(F32="",G32=""),"size?",IF(I32="","exposed Y/N?",IF(H32="","qty?",IF(B32="OTHER","OTHER: no rate, price it under hardware","OK")))))) | S32: {=IF(OR(O32="",M32=""),"",IF(B32="MERANTI",RATES!$C$45,IFERROR(INDEX(RATES!$C:$C,MATCH(B32&"_"&SUBSTITUTE(O32,"-CURVED","C"),RATES!$A:$A,0)),"rate?")))} | T32: =IF(ISNUMBER(S32),M32*S32,"")
A33: METAL (hollow steel): one line per part, priced PER METRE from the RATES hollow list. MATERIAL = hollow code HOLLOW-<a>x<b>x<wall>, or METAL (= section W x T with RATES!HOLLOW_WALL)
A34: NO | B34: MATERIAL / HOLLOW CODE | C34: LABEL | D34: COMPONENT | E34: L mm | F34: W mm | G34: T mm | H34: QTY | I34: EXPOSED Y/N | L34: NOTE | M34: LENGTH m (calc) | N34: FACE m² (calc) | O34: CODE USED (calc) | R34: CHECK (calc) | S34: RATE IDR/m (system) | T34: COST IDR (system) | U34: COST USD (system)
A35: 1 | M35: =IF(E35="","",E35/1000*IF(H35="",1,H35)) | N35: =IF(OR(E35="",F35=""),"",E35*F35/1000000*IF(H35="",1,H35)) | O35: =IF(E35="","",IF(UPPER(B35)="METAL",IFERROR(IFERROR(INDEX(RATES!$A:$A,MATCH("HOLLOW-"&MIN(F35,G35)&"x"&MAX(F35,G35)&"x"&SUBSTITUTE(RATES!$C$252&"",",","."),RATES!$A:$A,0)),IFERROR(INDEX(RATES!$A:$A,MATCH("HOLLOW-"&MIN(F35,G35)&"x"&MAX(F35,G35)&"x"&"1",RATES!$A:$A,0)),IFERROR(INDEX(RATES!$A:$A,MATCH("HOLLOW-"&MIN(F35,G35)&"x"&MAX(F35,G35)&"x"&"1.2",RATES!$A:$A,0)),INDEX(RATES!$A:$A,MATCH("HOLLOW-"&MIN(F35,G35)&"x"&MAX(F35,G35)&"x"&"1.5",RATES!$A:$A,0))))),"not in list"),IFERROR(INDEX(RATES!$A:$A,MATCH(IF(LEFT(UPPER(B35),7)="HOLLOW-",UPPER(B35),"HOLLOW-"&B35),RATES!$A:$A,0)),"not in list"))) | R35: =IF(E35="","",IF(B35="","material?",IF(OR(F35="",G35=""),"size?",IF(I35="","exposed Y/N?",IF(H35="","qty?",IF(O35="not in list","hollow code?","OK")))))) | S35: =IF(E35="","",IFERROR(INDEX(RATES!$C:$C,MATCH(O35,RATES!$A:$A,0)),"rate?")) | T35: =IF(AND(ISNUMBER(S35),ISNUMBER(M35)),M35*S35,"") | U35: =IF(T35="","",T35/RATES!$C$172)
A36: 2 | M36: =IF(E36="","",E36/1000*IF(H36="",1,H36)) | N36: =IF(OR(E36="",F36=""),"",E36*F36/1000000*IF(H36="",1,H36)) | O36: =IF(E36="","",IF(UPPER(B36)="METAL",IFERROR(IFERROR(INDEX(RATES!$A:$A,MATCH("HOLLOW-"&MIN(F36,G36)&"x"&MAX(F36,G36)&"x"&SUBSTITUTE(RATES!$C$252&"",",","."),RATES!$A:$A,0)),IFERROR(INDEX(RATES!$A:$A,MATCH("HOLLOW-"&MIN(F36,G36)&"x"&MAX(F36,G36)&"x"&"1",RATES!$A:$A,0)),IFERROR(INDEX(RATES!$A:$A,MATCH("HOLLOW-"&MIN(F36,G36)&"x"&MAX(F36,G36)&"x"&"1.2",RATES!$A:$A,0)),INDEX(RATES!$A:$A,MATCH("HOLLOW-"&MIN(F36,G36)&"x"&MAX(F36,G36)&"x"&"1.5",RATES!$A:$A,0))))),"not in list"),IFERROR(INDEX(RATES!$A:$A,MATCH(IF(LEFT(UPPER(B36),7)="HOLLOW-",UPPER(B36),"HOLLOW-"&B36),RATES!$A:$A,0)),"not in list"))) | R36: =IF(E36="","",IF(B36="","material?",IF(OR(F36="",G36=""),"size?",IF(I36="","exposed Y/N?",IF(H36="","qty?",IF(O36="not in list","hollow code?","OK")))))) | S36: =IF(E36="","",IFERROR(INDEX(RATES!$C:$C,MATCH(O36,RATES!$A:$A,0)),"rate?")) | T36: =IF(AND(ISNUMBER(S36),ISNUMBER(M36)),M36*S36,"") | U36: =IF(T36="","",T36/RATES!$C$172)
A37: 3 | M37: =IF(E37="","",E37/1000*IF(H37="",1,H37)) | N37: =IF(OR(E37="",F37=""),"",E37*F37/1000000*IF(H37="",1,H37)) | O37: =IF(E37="","",IF(UPPER(B37)="METAL",IFERROR(IFERROR(INDEX(RATES!$A:$A,MATCH("HOLLOW-"&MIN(F37,G37)&"x"&MAX(F37,G37)&"x"&SUBSTITUTE(RATES!$C$252&"",",","."),RATES!$A:$A,0)),IFERROR(INDEX(RATES!$A:$A,MATCH("HOLLOW-"&MIN(F37,G37)&"x"&MAX(F37,G37)&"x"&"1",RATES!$A:$A,0)),IFERROR(INDEX(RATES!$A:$A,MATCH("HOLLOW-"&MIN(F37,G37)&"x"&MAX(F37,G37)&"x"&"1.2",RATES!$A:$A,0)),INDEX(RATES!$A:$A,MATCH("HOLLOW-"&MIN(F37,G37)&"x"&MAX(F37,G37)&"x"&"1.5",RATES!$A:$A,0))))),"not in list"),IFERROR(INDEX(RATES!$A:$A,MATCH(IF(LEFT(UPPER(B37),7)="HOLLOW-",UPPER(B37),"HOLLOW-"&B37),RATES!$A:$A,0)),"not in list"))) | R37: =IF(E37="","",IF(B37="","material?",IF(OR(F37="",G37=""),"size?",IF(I37="","exposed Y/N?",IF(H37="","qty?",IF(O37="not in list","hollow code?","OK")))))) | S37: =IF(E37="","",IFERROR(INDEX(RATES!$C:$C,MATCH(O37,RATES!$A:$A,0)),"rate?")) | T37: =IF(AND(ISNUMBER(S37),ISNUMBER(M37)),M37*S37,"") | U37: =IF(T37="","",T37/RATES!$C$172)
A38: 4 | M38: =IF(E38="","",E38/1000*IF(H38="",1,H38)) | N38: =IF(OR(E38="",F38=""),"",E38*F38/1000000*IF(H38="",1,H38)) | O38: =IF(E38="","",IF(UPPER(B38)="METAL",IFERROR(IFERROR(INDEX(RATES!$A:$A,MATCH("HOLLOW-"&MIN(F38,G38)&"x"&MAX(F38,G38)&"x"&SUBSTITUTE(RATES!$C$252&"",",","."),RATES!$A:$A,0)),IFERROR(INDEX(RATES!$A:$A,MATCH("HOLLOW-"&MIN(F38,G38)&"x"&MAX(F38,G38)&"x"&"1",RATES!$A:$A,0)),IFERROR(INDEX(RATES!$A:$A,MATCH("HOLLOW-"&MIN(F38,G38)&"x"&MAX(F38,G38)&"x"&"1.2",RATES!$A:$A,0)),INDEX(RATES!$A:$A,MATCH("HOLLOW-"&MIN(F38,G38)&"x"&MAX(F38,G38)&"x"&"1.5",RATES!$A:$A,0))))),"not in list"),IFERROR(INDEX(RATES!$A:$A,MATCH(IF(LEFT(UPPER(B38),7)="HOLLOW-",UPPER(B38),"HOLLOW-"&B38),RATES!$A:$A,0)),"not in list"))) | R38: =IF(E38="","",IF(B38="","material?",IF(OR(F38="",G38=""),"size?",IF(I38="","exposed Y/N?",IF(H38="","qty?",IF(O38="not in list","hollow code?","OK")))))) | S38: =IF(E38="","",IFERROR(INDEX(RATES!$C:$C,MATCH(O38,RATES!$A:$A,0)),"rate?")) | T38: =IF(AND(ISNUMBER(S38),ISNUMBER(M38)),M38*S38,"") | U38: =IF(T38="","",T38/RATES!$C$172)
A39: 5 | M39: =IF(E39="","",E39/1000*IF(H39="",1,H39)) | N39: =IF(OR(E39="",F39=""),"",E39*F39/1000000*IF(H39="",1,H39)) | O39: =IF(E39="","",IF(UPPER(B39)="METAL",IFERROR(IFERROR(INDEX(RATES!$A:$A,MATCH("HOLLOW-"&MIN(F39,G39)&"x"&MAX(F39,G39)&"x"&SUBSTITUTE(RATES!$C$252&"",",","."),RATES!$A:$A,0)),IFERROR(INDEX(RATES!$A:$A,MATCH("HOLLOW-"&MIN(F39,G39)&"x"&MAX(F39,G39)&"x"&"1",RATES!$A:$A,0)),IFERROR(INDEX(RATES!$A:$A,MATCH("HOLLOW-"&MIN(F39,G39)&"x"&MAX(F39,G39)&"x"&"1.2",RATES!$A:$A,0)),INDEX(RATES!$A:$A,MATCH("HOLLOW-"&MIN(F39,G39)&"x"&MAX(F39,G39)&"x"&"1.5",RATES!$A:$A,0))))),"not in list"),IFERROR(INDEX(RATES!$A:$A,MATCH(IF(LEFT(UPPER(B39),7)="HOLLOW-",UPPER(B39),"HOLLOW-"&B39),RATES!$A:$A,0)),"not in list"))) | R39: =IF(E39="","",IF(B39="","material?",IF(OR(F39="",G39=""),"size?",IF(I39="","exposed Y/N?",IF(H39="","qty?",IF(O39="not in list","hollow code?","OK")))))) | S39: =IF(E39="","",IFERROR(INDEX(RATES!$C:$C,MATCH(O39,RATES!$A:$A,0)),"rate?")) | T39: =IF(AND(ISNUMBER(S39),ISNUMBER(M39)),M39*S39,"") | U39: =IF(T39="","",T39/RATES!$C$172)
A40: 6 | M40: =IF(E40="","",E40/1000*IF(H40="",1,H40)) | N40: =IF(OR(E40="",F40=""),"",E40*F40/1000000*IF(H40="",1,H40)) | O40: =IF(E40="","",IF(UPPER(B40)="METAL",IFERROR(IFERROR(INDEX(RATES!$A:$A,MATCH("HOLLOW-"&MIN(F40,G40)&"x"&MAX(F40,G40)&"x"&SUBSTITUTE(RATES!$C$252&"",",","."),RATES!$A:$A,0)),IFERROR(INDEX(RATES!$A:$A,MATCH("HOLLOW-"&MIN(F40,G40)&"x"&MAX(F40,G40)&"x"&"1",RATES!$A:$A,0)),IFERROR(INDEX(RATES!$A:$A,MATCH("HOLLOW-"&MIN(F40,G40)&"x"&MAX(F40,G40)&"x"&"1.2",RATES!$A:$A,0)),INDEX(RATES!$A:$A,MATCH("HOLLOW-"&MIN(F40,G40)&"x"&MAX(F40,G40)&"x"&"1.5",RATES!$A:$A,0))))),"not in list"),IFERROR(INDEX(RATES!$A:$A,MATCH(IF(LEFT(UPPER(B40),7)="HOLLOW-",UPPER(B40),"HOLLOW-"&B40),RATES!$A:$A,0)),"not in list"))) | R40: =IF(E40="","",IF(B40="","material?",IF(OR(F40="",G40=""),"size?",IF(I40="","exposed Y/N?",IF(H40="","qty?",IF(O40="not in list","hollow code?","OK")))))) | S40: =IF(E40="","",IFERROR(INDEX(RATES!$C:$C,MATCH(O40,RATES!$A:$A,0)),"rate?")) | T40: =IF(AND(ISNUMBER(S40),ISNUMBER(M40)),M40*S40,"") | U40: =IF(T40="","",T40/RATES!$C$172)
A41: 7 | M41: =IF(E41="","",E41/1000*IF(H41="",1,H41)) | N41: =IF(OR(E41="",F41=""),"",E41*F41/1000000*IF(H41="",1,H41)) | O41: =IF(E41="","",IF(UPPER(B41)="METAL",IFERROR(IFERROR(INDEX(RATES!$A:$A,MATCH("HOLLOW-"&MIN(F41,G41)&"x"&MAX(F41,G41)&"x"&SUBSTITUTE(RATES!$C$252&"",",","."),RATES!$A:$A,0)),IFERROR(INDEX(RATES!$A:$A,MATCH("HOLLOW-"&MIN(F41,G41)&"x"&MAX(F41,G41)&"x"&"1",RATES!$A:$A,0)),IFERROR(INDEX(RATES!$A:$A,MATCH("HOLLOW-"&MIN(F41,G41)&"x"&MAX(F41,G41)&"x"&"1.2",RATES!$A:$A,0)),INDEX(RATES!$A:$A,MATCH("HOLLOW-"&MIN(F41,G41)&"x"&MAX(F41,G41)&"x"&"1.5",RATES!$A:$A,0))))),"not in list"),IFERROR(INDEX(RATES!$A:$A,MATCH(IF(LEFT(UPPER(B41),7)="HOLLOW-",UPPER(B41),"HOLLOW-"&B41),RATES!$A:$A,0)),"not in list"))) | R41: =IF(E41="","",IF(B41="","material?",IF(OR(F41="",G41=""),"size?",IF(I41="","exposed Y/N?",IF(H41="","qty?",IF(O41="not in list","hollow code?","OK")))))) | S41: =IF(E41="","",IFERROR(INDEX(RATES!$C:$C,MATCH(O41,RATES!$A:$A,0)),"rate?")) | T41: =IF(AND(ISNUMBER(S41),ISNUMBER(M41)),M41*S41,"") | U41: =IF(T41="","",T41/RATES!$C$172)
A42: 8 | M42: =IF(E42="","",E42/1000*IF(H42="",1,H42)) | N42: =IF(OR(E42="",F42=""),"",E42*F42/1000000*IF(H42="",1,H42)) | O42: =IF(E42="","",IF(UPPER(B42)="METAL",IFERROR(IFERROR(INDEX(RATES!$A:$A,MATCH("HOLLOW-"&MIN(F42,G42)&"x"&MAX(F42,G42)&"x"&SUBSTITUTE(RATES!$C$252&"",",","."),RATES!$A:$A,0)),IFERROR(INDEX(RATES!$A:$A,MATCH("HOLLOW-"&MIN(F42,G42)&"x"&MAX(F42,G42)&"x"&"1",RATES!$A:$A,0)),IFERROR(INDEX(RATES!$A:$A,MATCH("HOLLOW-"&MIN(F42,G42)&"x"&MAX(F42,G42)&"x"&"1.2",RATES!$A:$A,0)),INDEX(RATES!$A:$A,MATCH("HOLLOW-"&MIN(F42,G42)&"x"&MAX(F42,G42)&"x"&"1.5",RATES!$A:$A,0))))),"not in list"),IFERROR(INDEX(RATES!$A:$A,MATCH(IF(LEFT(UPPER(B42),7)="HOLLOW-",UPPER(B42),"HOLLOW-"&B42),RATES!$A:$A,0)),"not in list"))) | R42: =IF(E42="","",IF(B42="","material?",IF(OR(F42="",G42=""),"size?",IF(I42="","exposed Y/N?",IF(H42="","qty?",IF(O42="not in list","hollow code?","OK")))))) | S42: =IF(E42="","",IFERROR(INDEX(RATES!$C:$C,MATCH(O42,RATES!$A:$A,0)),"rate?")) | T42: =IF(AND(ISNUMBER(S42),ISNUMBER(M42)),M42*S42,"") | U42: =IF(T42="","",T42/RATES!$C$172)
A44: PANELS: one line per panel, L × W in mm, T = board thickness, qty per item. No size (round, oversize, laminated): enter SHEETS (manual)
...

Sheet RATES
A1: RATES: PLV BOM Rate Card 29 Sep 26 (rates_version 2026-09-29), with the 30 Sep changes: finishing split into four rates, 40 × 40 section rule
A2: Blue = base figure (change it and every cost in this workbook follows). Black = formula. Item tabs look rates up by the code in column A. Only the rate owner edits this tab.
A3: Same rate card as the PLV BOM Costing Workbook v3 (teak, mindi, meranti, plywood). Plywood keeps the Mojo Indah Sep 2026 rates; columns F and G show the Linyi Ocean landed quote of 16 Oct 2026 in USD and IDR for comparison. MDF, marine plywood (rows 170 onward) and DTC rails and hinges (rows 227–229) are priced from USD. Orange rows = rate with both a USD and an IDR price. No rates yet for oak / ash, oak veneer, rattan or metal frames.
A4: code | B4: Description | C4: Value | D4: Unit | E4: Source | F4: Quote USD (Linyi Ocean landed, 16 Oct 2026) | G4: Quote IDR (USD × FX_USD)
A5: BASE FIGURES: STMV (Standard Maldives) ledger, payroll and vendor lists
A6: log_teak | B6: Teak log price, implied | C6: 6000000 | D6: IDR/m³ | E6: Ledger 152.3m ÷ 14 m³. Status CONFIRM: replace with nota price
A7: log_mindi | B7: Mindi log price, implied | C7: 3000000 | D7: IDR/m³ | E7: Ledger 126.1m ÷ 41 m³. Status CONFIRM
A8: meranti_sawn | B8: Meranti dry sawn timber | C8: 8500000 | D8: IDR/m³ | E8: STMV BOM price. Status CONFIRM
A9: processing | B9: Wood processing (kiln + sawmill + hauling + sawmill staff), per m³ of log | C9: 598978 | D9: IDR/m³ | E9: Ledger ÷ 75.82 m³ teak + mindi
A10: carp_pool | B10: Carpentry payroll pool Mar–Sep 2026 | C10: 270175017 | D10: IDR | E10: Payroll categorised by name, 29 Sep
A11: carp_deduct | B11: Less panel cutting / pressing (already in panel rate) | C11: 0.1 | D11: % | E11: Decision 29 Sep
A12: comp_m3 | B12: STMV solid wood in components (teak 12.21 + mindi 13.15 + meranti 7.20) | C12: 32.56 | D12: m³ | E12: REVISI BOM 21 MEI 26
A13: yield_A | B13: Yield factor tier A (exposed, straight, ≥ 1000 mm) | C13: 3.5 | D13: x | E13: Judgement, open item
A14: yield_AC | B14: Yield factor tier A-CURVED / wide board | C14: 4.6 | D14: x | E14: STMV mindi
A15: yield_B | B15: Yield factor tier B (exposed < 1000 mm, or section ≤ 40 × 40 up to 1500 mm) | C15: 2.5 | D15: x | E15: Judgement, open item
A16: yield_C | B16: Yield factor tier C (not exposed) | C16: 2 | D16: x | E16: STMV teak
A17: yield_D | B17: Yield factor tier D (very small parts) | C17: 1.5 | D17: x | E17: Judgement, open item
... A32: ven_labour | B32: Pressing labour per face (tape, press, sand, cut) | C32: 57142.86 | D32: IDR/face | E32: 800,000 ÷ 14 sheets. Status CONFIRM
A33: RATE CARD: applied by the item tabs
A34: LAB_CARP | B34: Carpentry labour per m³ of component (inside every tier rate) | C34: 4000000 | D34: IDR/m³ | E34: Pool less 10% ÷ component m³
A35: TEAK_A | B35: Teak tier A | C35: 27507965 | D35: IDR/m³ | E35: (log + processing) × yield + labour
A36: TEAK_AC | B36: Teak tier A-CURVED | C36: 34040953 | D36: IDR/m³
A37: TEAK_B | B37: Teak tier B | C37: 21568885 | D37: IDR/m³
A38: TEAK_C | B38: Teak tier C | C38: 18599345 | D38: IDR/m³
A39: TEAK_D | B39: Teak tier D | C39: 15629805 | D39: IDR/m³
A40: MINDI_A | B40: Mindi tier A | C40: 11918257 | D40: IDR/m³
A41: MINDI_AC | B41: Mindi tier A-CURVED | C41: 14269829 | D41: IDR/m³
A42: MINDI_B | B42: Mindi tier B | C42: 9780464 | D42: IDR/m³
A43: MINDI_C | B43: Mindi tier C | C43: 8711567.6 | D43: IDR/m³
A44: MINDI_D | B44: Mindi tier D | C44: 7642671.1 | D44: IDR/m³
A45: MERANTI | B45: Meranti, any tier | C45: 18196184 | D45: IDR/m³ | E45: Sawn price × yield + labour, no processing
A46: FASTENERS | B46: Screws, nails, dowels, glue per m³ of component | C46: 1000000 | D46: IDR/m³
A47: FIN_MAT | B47: Finishing materials (Zhanchen + thinner) per m² exposed | C47: 37000 | D47: IDR/m²
A48: SAND_MAT | B48: Sanding materials (abrasives) per m² exposed | C48: 10235.642 | D48: IDR/m²
A49: SAND_LAB | B49: Sanding labour (65% of sanding pool) per m² exposed | C49: 20000 | D49: IDR/m²
A50: FIN_LAB | B50: Finishing labour (finishing pool) per m² exposed | C50: 45000 | D50: IDR/m²
A51: CARTON_M2 | B51: Carton + consumables per m² of carton board (6 sides) | C51: 40000 | D51: IDR/m² | E51: Cartons 59.4m + 40% of other packing materials
A52: PACK_LAB | B52: Packing labour per m³ of carton | C52: 50000 | D52: IDR/m³ | E52: 6 people × 8 days per container. Status CONFIRM
A53: GRP_A | B53: Carton group A price (boxes under CARTON_MIN_M2) | C53: 24000 | D53: IDR | E53: STMV carton groups, 28 Sep
A54: MISC_PCT | B54: Miscellaneous, × direct cost | C54: 0.04 | D54: % | E54: Rizky 23 Okt 2026: 4% of TOTAL COST (was 5%)
...

Sheet LISTS
A1: Dropdown lists and thresholds. Do not rename or move.
A2: SOLID_SPECIES | B2: PANEL_TYPE | C2: FINISH_RECIPE | D2: YN | E2: NORM | F2: VALUE
A3: TEAK | B3: LND-PLY-E0-3 | C3: NC NATURAL | D3: Y | E3: TIER_A_MIN_LEN mm | F3: 1000
A4: MINDI | B4: LND-PLY-E0-6 | C4: PU DUCO | D4: N | E4: TIER_D_MAX_VOL m3 | F4: 0.0005
A5: MERANTI | B5: LND-PLY-E0-9 | C5: NC + GLAZE | E5: TIER_D_MAX_LEN mm | F5: 300
A6: OTHER | B6: LND-PLY-E0-12 | C6: NONE (RAW) | E6: SHEET_L mm | F6: 2440
B7: LND-PLY-E0-15 | C7: OTHER | E7: SHEET_W mm | F7: 1220
B8: LND-PLY-E0-18 | E8: SHEET_KERF mm | F8: 5
B9: LND-MDF-E0-3 | E9: CARTON_ADD mm | F9: 40
B10: LND-MDF-E0-6 | E10: NARROW_MAX_SECTION mm | F10: 40
B11: LND-MDF-E0-9 | E11: NARROW_MAX_LEN mm | F11: 1500
B12: LND-MDF-E0-12
B13: LND-MDF-E0-15
B14: LND-MDF-E0-18
B15: LND-PLY-E0-3-MSF
B16: LND-PLY-E0-3-MSF-V10
B17: LND-PLY-E0-3-MSF-V12
B18: LND-PLY-E0-3-MDF
B19: LND-PLY-E0-3-MDF-V10
B20: LND-PLY-E0-3-MDF-V12
B21: LND-PLY-E0-6-MSF
B22: LND-PLY-E0-6-MSF-V10
B23: LND-PLY-E0-6-MSF-V12
... B86: LND-MDF-E0-18-MDF-V12

Sheet LV453-B61
A1: ITEM CODE | C1: LV453-B61 | D1: OVERALL L mm | G1: {=IFERROR(IF(INDEX(ITEMS!$E$5:$E$120,MATCH($C$1,ITEMS!$C$5:$C$120,0))="","",INDEX(ITEMS!$E$5:$E$120,MATCH($C$1,ITEMS!$C$5:$C$120,0))),"")} | L1: =IF(G6="","photo",_xludf.IMAGE(G6))
A2: ITEM NAME | C2: {=IFERROR(IF(INDEX(ITEMS!$D$5:$D$120,MATCH($C$1,ITEMS!$C$5:$C$120,0))="","",INDEX(ITEMS!$D$5:$D$120,MATCH($C$1,ITEMS!$C$5:$C$120,0))),"")} | D2: OVERALL W mm | G2: {=IFERROR(IF(INDEX(ITEMS!$F$5:$F$120,MATCH($C$1,ITEMS!$C$5:$C$120,0))="","",INDEX(ITEMS!$F$5:$F$120,MATCH($C$1,ITEMS!$C$5:$C$120,0))),"")}
A3: COLLECTION / ROOM | C3: {=IFERROR(INDEX(ITEMS!$B$5:$B$120,MATCH($C$1,ITEMS!$C$5:$C$120,0))&" / "&INDEX(ITEMS!$W$5:$W$120,MATCH($C$1,ITEMS!$C$5:$C$120,0)),"")} | D3: OVERALL H mm | G3: {=IFERROR(IF(INDEX(ITEMS!$G$5:$G$120,MATCH($C$1,ITEMS!$C$5:$C$120,0))="","",INDEX(ITEMS!$G$5:$G$120,MATCH($C$1,ITEMS!$C$5:$C$120,0))),"")}
A4: ORDER QTY | C4: {=IFERROR(IF(INDEX(ITEMS!$H$5:$H$120,MATCH($C$1,ITEMS!$C$5:$C$120,0))="","",INDEX(ITEMS!$H$5:$H$120,MATCH($C$1,ITEMS!$C$5:$C$120,0))),"")} | D4: LV453 - B61 - DRESSER 6 DRAWERS.pdf | G4: {=IFERROR(IF(INDEX(ITEMS!$I$5:$I$120,MATCH($C$1,ITEMS!$C$5:$C$120,0))="","",INDEX(ITEMS!$I$5:$I$120,MATCH($C$1,ITEMS!$C$5:$C$120,0))),"")}
A5: FINISH RECIPE | C5: NC NATURAL | D5: SPEC LINK | G5: {=IFERROR(IF(INDEX(ITEMS!$V$5:$V$120,MATCH($C$1,ITEMS!$C$5:$C$120,0))="","",INDEX(ITEMS!$V$5:$V$120,MATCH($C$1,ITEMS!$C$5:$C$120,0))),"")}
A6: FLATPACK? (Y/N) | C6: N | D6: PHOTO LINK
A7: NOTES | C7: {=IFERROR(IF(INDEX(ITEMS!$X$5:$X$120,MATCH($C$1,ITEMS!$C$5:$C$120,0))="","",INDEX(ITEMS!$X$5:$X$120,MATCH($C$1,ITEMS!$C$5:$C$120,0))),"")} | D7: REVISION / DATE
A9: PACKING: assembled = leave boxes blank (system uses overall size + 40 mm as 1 carton). Flatpack = one row per box.
A10: BOX | B10: CONTENTS | D10: L mm | E10: W mm | F10: H mm | G10: QTY | H10: CARTON L | I10: CARTON W | J10: CARTON H | L10: m² 6 sides (calc) | M10: m³ (calc)
A11: 1 | H11: =IF(D11="","",D11+LISTS!$F$9) | I11: =IF(E11="","",E11+LISTS!$F$9) | J11: =IF(F11="","",F11+LISTS!$F$9) | L11: =IF(H11="","",2*(H11*I11+H11*J11+I11*J11)/1000000*IF(G11="",1,G11)) | M11: =IF(H11="","",H11*I11*J11/1000000000*IF(G11="",1,G11))
A12: 2 | H12: =IF(D12="","",D12+LISTS!$F$9) | I12: =IF(E12="","",E12+LISTS!$F$9) | J12: =IF(F12="","",F12+LISTS!$F$9) | L12: =IF(H12="","",2*(H12*I12+H12*J12+I12*J12)/1000000*IF(G12="",1,G12)) | M12: =IF(H12="","",H12*I12*J12/1000000000*IF(G12="",1,G12))
A13: 3 | H13: =IF(D13="","",D13+LISTS!$F$9) | I13: =IF(E13="","",E13+LISTS!$F$9) | J13: =IF(F13="","",F13+LISTS!$F$9) | L13: =IF(H13="","",2*(H13*I13+H13*J13+I13*J13)/1000000*IF(G13="",1,G13)) | M13: =IF(H13="","",H13*I13*J13/1000000000*IF(G13="",1,G13))
A14: 4 | H14: =IF(D14="","",D14+LISTS!$F$9) | I14: =IF(E14="","",E14+LISTS!$F$9) | J14: =IF(F14="","",F14+LISTS!$F$9) | L14: =IF(H14="","",2*(H14*I14+H14*J14+I14*J14)/1000000*IF(G14="",1,G14)) | M14: =IF(H14="","",H14*I14*J14/1000000000*IF(G14="",1,G14))
A15: TOTAL | G15: =IF(D11="",1,SUM(G11:G14)+COUNTIFS(D11:D14,"<>",G11:G14,"")) | H15: cartons | L15: =IF(D11="",IF(OR(G1="",G2="",G3=""),0,2*((G1+LISTS!$F$9)*(G2+LISTS!$F$9)+(G1+LISTS!$F$9)*(G3+LISTS!$F$9)+(G2+LISTS!$F$9)*(G3+LISTS!$F$9))/1000000),SUM(L11:L14)) | M15: =IF(D11="",IF(OR(G1="",G2="",G3=""),0,(G1+LISTS!$F$9)*(G2+LISTS!$F$9)*(G3+LISTS!$F$9)/1000000000),SUM(M11:M14))
A16: SOLID WOOD: one line per component, mm, qty per ONE item
A17: NO | B17: MATERIAL | C17: LABEL | D17: COMPONENT | E17: L mm | F17: W mm | G17: T mm | H17: QTY | I17: EXPOSED Y/N | J17: CURVED Y/N | K17: TIER OVERRIDE | L17: NOTE | M17: VOL m³ (calc) | N17: FACE m² (calc) | O17: AUTO TIER (calc) | R17: CHECK (calc) | S17: RATE (system) | T17: COST IDR (system)
A18: 1 | B18: MINDI | C18: 3 / A | D18: Tiang Kaki Luar (Corner Posts) | E18: 820 | F18: 45 | G18: 45 | H18: 4 | I18: Y | J18: N | L18: Part 3 / Code A (Solid wood 45x45) | P-01 | M18: =IF(OR(E18="",F18="",G18=""),"",E18*F18*G18/1000000000*IF(H18="",1,H18)) | N18: =IF(OR(E18="",F18=""),"",E18*F18/1000000*IF(H18="",1,H18)) | O18: =IF(E18="","",IF(K18<>"",K18,IF(AND(E18*F18*G18/1000000000<LISTS!$F$4,MAX(E18,F18,G18)<LISTS!$F$5),"D",IF(I18="N","C",IF(J18="Y","A-CURVED",IF(AND(MEDIAN(E18,F18,G18)<=LISTS!$F$10,MAX(E18,F18,G18)<=LISTS!$F$11),"B",IF(MAX(E18,F18,G18)>=LISTS!$F$3,"A","B"))))))) | R18: =IF(E18="","",IF(B18="","material?",IF(OR(F18="",G18=""),"size?",IF(I18="","exposed Y/N?",IF(H18="","qty?",IF(B18="OTHER","OTHER: no rate, price it under hardware","OK")))))) | S18: {=IF(OR(O18="",M18=""),"",IF(B18="MERANTI",RATES!$C$45,IFERROR(INDEX(RATES!$C:$C,MATCH(B18&"_"&SUBSTITUTE(O18,"-CURVED","C"),RATES!$A:$A,0)),"rate?")))} | T18: =IF(ISNUMBER(S18),M18*S18,"")
A19: 2 | B19: MINDI | C19: 3 / A | D19: Tiang Kaki Tengah (Center Posts) | E19: 820 | F19: 45 | G19: 45 | H19: 2 | I19: Y | J19: N | L19: Part 3 / Code A (Solid wood 45x45) | P-02 | M19: =IF(OR(E19="",F19="",G19=""),"",E19*F19*G19/1000000000*IF(H19="",1,H19)) | N19: =IF(OR(E19="",F19=""),"",E19*F19/1000000*IF(H19="",1,H19)) | O19: =IF(E19="","",IF(K19<>"",K19,IF(AND(E19*F19*G19/1000000000<LISTS!$F$4,MAX(E19,F19,G19)<LISTS!$F$5),"D",IF(I19="N","C",IF(J19="Y","A-CURVED",IF(AND(MEDIAN(E19,F19,G19)<=LISTS!$F$10,MAX(E19,F19,G19)<=LISTS!$F$11),"B",IF(MAX(E19,F19,G19)>=LISTS!$F$3,"A","B"))))))) | R19: =IF(E19="","",IF(B19="","material?",IF(OR(F19="",G19=""),"size?",IF(I19="","exposed Y/N?",IF(H19="","qty?",IF(B19="OTHER","OTHER: no rate, price it under hardware","OK")))))) | S19: {=IF(OR(O19="",M19=""),"",IF(B19="MERANTI",RATES!$C$45,IFERROR(INDEX(RATES!$C:$C,MATCH(B19&"_"&SUBSTITUTE(O19,"-CURVED","C"),RATES!$A:$A,0)),"rate?")))} | T19: =IF(ISNUMBER(S19),M19*S19,"")
A20: 3 | B20: MINDI | C20: 14 / A | D20: Rel Depan Atas (Top Front Rail) | E20: 1410 | F20: 45 | G20: 30 | H20: 1 | I20: Y | J20: N | L20: Part 14 / Code A (Solid wood 45x30) | P-03 | M20: =IF(OR(E20="",F20="",G20=""),"",E20*F20*G20/1000000000*IF(H20="",1,H20)) | N20: =IF(OR(E20="",F20=""),"",E20*F20/1000000*IF(H20="",1,H20)) | O20: =IF(E20="","",IF(K20<>"",K20,IF(AND(E20*F20*G20/1000000000<LISTS!$F$4,MAX(E20,F20,G20)<LISTS!$F$5),"D",IF(I20="N","C",IF(J20="Y","A-CURVED",IF(AND(MEDIAN(E20,F20,G20)<=LISTS!$F$10,MAX(E20,F20,G20)<=LISTS!$F$11),"B",IF(MAX(E20,F20,G20)>=LISTS!$F$3,"A","B"))))))) | R20: =IF(E20="","",IF(B20="","material?",IF(OR(F20="",G20=""),"size?",IF(I20="","exposed Y/N?",IF(H20="","qty?",IF(B20="OTHER","OTHER: no rate, price it under hardware","OK")))))) | S20: {=IF(OR(O20="",M20=""),"",IF(B20="MERANTI",RATES!$C$45,IFERROR(INDEX(RATES!$C:$C,MATCH(B20&"_"&SUBSTITUTE(O20,"-CURVED","C"),RATES!$A:$A,0)),"rate?")))} | T20: =IF(ISNUMBER(S20),M20*S20,"")
